Workbook

Sheet 34-B
C9: PERIODO : | E9: DEL 02 DE FEBRERO AL 01 DE MARZO 2026 | AB9: ORIGEN: | AD9: PARQUE DE LA BOMBILLA | AI9: - | AJ9: DESTINO: | AL9: CENTRO COMERCIAL SANTA FE
C10: RUTA : | E10: 34-B | AB10: MODALIDAD : | AE10: ECOBÚS
P11: Lunes a Viernes | AC11: Sábado | AP11: Domingo
F12: No de credencial | I12: Descansos en el periodo | P12: 1er Turno | T12: 2do Turno | W12: 3er Turno | Y12: Termino | AC12: 1er Turno | AG12: 2do Turno | AJ12: 3er Turno | AL12: Termino | AP12: 1er Turno | AT12: 2do Turno | AW12: 3er Turno | AY12: Termino
C13: No | D13: Economico | E13: Sistema | F13: 1er Turno | G13: 2do Turno | H13: 3er Turno | I13: L | J13: M | K13: Mi | L13: J | M13: V | N13: S | O13: D | P13: Hora inicio Turno | Q13: Hora inicio en CC | R13: Lugar Inicio 1 | S13: Hora termino Turno 1 | T13: Lugar Inicio 2 | U13: Hora inicio 2 | V13: Hora termino Turno 2 | W13: Lugar Inicio 3 | X13: Hora Inicio Turno 3 | Y13: Hora Termino en CC | Z13: Lugar de termino CC | AA13: Termino en Modulo | AB13: Termino del Turno | AC13: Hora inicio Turno 1 __s__ | AD13: Hora inicio CC 1 __s__ | AE13: Lugar Inicio 1 __s__ | AF13: Hora termino Turno 1 __s__ | AG13: Lugar Inicio 2 __s__ | AH13: Hora inicio 2 __s__ | AI13: Hora termino Turno 2 __s__ | AJ13: Lugar Inicio 3 __s__ | AK13: Hora Inicio Turno 3 __s__ | AL13: Hora Termino en CC __s__ | AM13: Lugar de termino CC __s__ | AN13: Termino en Modulo __s__ | AO13: Termino del Turno __s__ | AP13: Hora inicio Turno 1 __d__ | AQ13: Hora inicio CC 1 __d__ | AR13: Lugar Inicio 1 __d__ | AS13: Hora termino Turno 1 __d__ | AT13: Lugar Inicio 2 __d__ | AU13: Hora inicio 2 __d__ | AV13: Hora termino Turno 2 __d__ | AW13: Lugar Inicio 3 __d__ | AX13: Hora Inicio Turno 3 __d__ | AY13: Hora Termino en CC __d__ | AZ13: Lugar de termino CC __d__ | BA13: Termino en Modulo __d__ | BB13: Termino del Turno __d__
I14: 2 | J14: =I14+1 -> 3 | K14: =J14+1 -> 4 | L14: =K14+1 -> 5 | M14: =L14+1 -> 6 | N14: =M14+1 -> 7 | O14: =N14+1 -> 8
I15: =O14+1 -> 9 | J15: =I15+1 -> 10 | K15: =J15+1 -> 11 | L15: =K15+1 -> 12 | M15: =L15+1 -> 13 | N15: =M15+1 -> 14 | O15: =N15+1 -> 15
I16: =O15+1 -> 16 | J16: =I16+1 -> 17 | K16: =J16+1 -> 18 | L16: =K16+1 -> 19 | M16: =L16+1 -> 20 | N16: =M16+1 -> 21 | O16: =N16+1 -> 22
I17: =O16+1 -> 23 | J17: =I17+1 -> 24 | K17: =J17+1 -> 25 | L17: =K17+1 -> 26 | M17: 27 | N17: 28 | O17: 1
Q20: 0.034722222 | U20: 0.03125 | X20: 0.03125 | Y20: 0.027777778 | AA20: 0.010416667 | AB20: 0.29166667
U21: 0.020833333
AD22: 0.03125
Y23: 0.041666667 | AA23: 0.010416667 | AL23: 0.041666667 | AN23: 0.010416667
C24: 1
C25: 2
C26: 3
C27: 4
C28: 5
C29: 6
C30: 7
C31: 8
C32: 9
C33: 10
C34: 11
C35: 12
... C50: 27
T52: .
C53: Cubre Descansos
I54: Servicios a cubrir
C55: No | D55: Economico | E55: Sistema | F55: 1er Turno | G55: 2do Turno | H55: 3er Turno | I55: L | J55: M | K55: Mi | L55: J | M55: V | N55: S | O55: D
C56: E | R56: Nomenclatura | X56: Económicos programados | AB56: =COUNT(D21:D48) -> 0
C57: F | S57: D | T57: Descanso | X57: Cubre Descansos | AB57: =COUNT(F53:F61) -> 0
C58: A | S58: P | T58: Presentarse | X58: Económicos de colchón | AB58: 6
C59: B | S59: A,B,C | T59: Cubre descansos
C60: C | S60: M02 | T60: Modulo
C61: D | S61: PQB | T61: BOMBILLA
S62: CSF | T62: SANTA FE
S83: AUTORIZÓ | AE83: Vo. Bo. | AQ83: PARTICIPO
D84: ELABORÓ
E87: _________________________________________________________________
...

Sheet 116-A
D9: PERIODO : | E9: ='34-B'!E9 -> DEL 02 DE FEBRERO AL 01 DE MARZO 2026 | AA9: ORIGEN - DESTINO : | AB9: RIO DE GUADALUPE - METRO GENERAL ANAYA
D10: RUTA : | E10: 116-A | AA10: MODALIDAD : | AB10: ORDINARIO
P11: Lunes a Viernes | AC11: Sábado | AP11: Domingo
F12: No de credencial | I12: Descansos en el periodo | P12: 1er Turno | T12: 2do Turno | W12: 3er Turno | Y12: Termino | AC12: 1er Turno | AG12: 2do Turno | AJ12: 3er Turno | AL12: Termino | AP12: 1er Turno | AT12: 2do Turno | AW12: 3er Turno | AY12: Termino
C13: No | D13: Economico | E13: Sistema | F13: 1er Turno | G13: 2do Turno | H13: 3er Turno | I13: L | J13: M | K13: Mi | L13: J | M13: V | N13: S | O13: D | P13: Hora inicio Turno 1 | Q13: Hora inicio en CC | R13: Lugar Inicio 1 | S13: Hora termino Turno 1 | T13: Lugar Inicio 2 | U13: Hora inicio 2 | V13: Hora termino Turno 2 | W13: Lugar Inicio 3 | X13: Hora Inicio Turno 3 | Y13: Hora Termino en CC | Z13: Lugar de termino CC | AA13: Termino en Modulo | AB13: Termino del Turno | AC13: Hora inicio Turno 1 __s__ | AD13: Hora inicio CC 1 __s__ | AE13: Lugar Inicio 1 __s__ | AF13: Hora termino Turno 1 __s__ | AG13: Lugar Inicio 2 __s__ | AH13: Hora inicio 2 __s__ | AI13: Hora termino Turno 2 __s__ | AJ13: Lugar Inicio 3 __s__ | AK13: Hora Inicio Turno 3 __s__ | AL13: Hora Termino en CC __s__ | AM13: Lugar de termino CC __s__ | AN13: Termino en Modulo __s__ | AO13: Termino del Turno __s__ | AP13: Hora inicio Turno 1 __d__ | AQ13: Hora inicio CC 1 __d__ | AR13: Lugar Inicio 1 __d__ | AS13: Hora termino Turno 1 __d__ | AT13: Lugar Inicio 2 __d__ | AU13: Hora inicio 2 __d__ | AV13: Hora termino Turno 2 __d__ | AW13: Lugar Inicio 3 __d__ | AX13: Hora Inicio Turno 3 __d__ | AY13: Hora Termino en CC __d__ | AZ13: Lugar de termino CC __d__ | BA13: Termino en Modulo __d__ | BB13: Termino del Turno __d__
I14: 2 | J14: =I14+1 -> 3 | K14: =J14+1 -> 4 | L14: =K14+1 -> 5 | M14: =L14+1 -> 6 | N14: =M14+1 -> 7 | O14: =N14+1 -> 8
I15: =O14+1 -> 9 | J15: =I15+1 -> 10 | K15: =J15+1 -> 11 | L15: =K15+1 -> 12 | M15: =L15+1 -> 13 | N15: =M15+1 -> 14 | O15: =N15+1 -> 15
I16: =O15+1 -> 16 | J16: =I16+1 -> 17 | K16: =J16+1 -> 18 | L16: =K16+1 -> 19 | M16: =L16+1 -> 20 | N16: =M16+1 -> 21 | O16: =N16+1 -> 22
I17: =O16+1 -> 23 | J17: =I17+1 -> 24 | K17: =J17+1 -> 25 | L17: =K17+1 -> 26 | M17: 27 | N17: 28 | O17: 1
Q20: 0.020833333 | U20: 0.041666667 | X20: 0.041666667 | Y20: 0.027777778 | AA20: 0.010416667 | AD20: 0.020833333 | AL20: 0.020833333 | AN20: 0.010416667
AB21: 0.29166667
C22: 1
C23: 2
C24: 3
C25: 4
C26: 5
C27: 6
C28: 7
C29: 8
C30: 9
C31: 10
C33: Cubre Descansos | Z33: Notas
I34: Servicios a cubrir
C35: No | D35: Economico | E35: Sistema | F35: 1er Turno | G35: 2do Turno | H35: 3er Turno | I35: L | J35: M | K35: Mi | L35: J | M35: V | N35: S | O35: D
C36: A | AM36: Para sistema E/S
C37: B | AM37: Solo aplica a operadores de los turnos 1 y 2, turno 3 siempre es T/F
AM38: ='34-B'!$Z$76 -> 0 | AN38: ='34-B'!$Z$77 -> 0 | AO38: ='34-B'!$Z$77 -> 0 | AP38: ='34-B'!$Z$77 -> 0 | AQ38: ='34-B'!$Z$77 -> 0 | AR38: ='34-B'!$Z$77 -> 0 | AS38: ='34-B'!$Z$77 -> 0 | AT38: ='34-B'!$Z$77 -> 0 | AU38: ='34-B'!$Z$77 -> 0 | ... AX38: ='34-B'!$Z$77 -> 0
AM39: ='34-B'!$Z$77 -> 0
AM40: ='34-B'!$Z$78 -> 0 | AN40: ='34-B'!$Z$79 -> 0 | AO40: ='34-B'!$Z$79 -> 0 | AP40: ='34-B'!$Z$79 -> 0 | AQ40: ='34-B'!$Z$79 -> 0 | AR40: ='34-B'!$Z$79 -> 0 | AS40: ='34-B'!$Z$79 -> 0 | AT40: ='34-B'!$Z$79 -> 0 | AU40: ='34-B'!$Z$79 -> 0 | ... AX40: ='34-B'!$Z$79 -> 0
AM41: ='34-B'!$Z$79 -> 0
E42: Jornada excepcional
I43: Presentarse | AM43: ESTE ROL PUEDE VARIAR DE ACUERDO A LAS NECESIDADES DEL SERVICIO
E44: Cred. | F44: Lugar | G44: Hora de Inicio | H44: Hora de Termino | I44: L | J44: M | K44: Mi | L44: J | M44: V | N44: S | O44: D
Q45: Económicos programados | T45: 9
Q46: Cubre Descansos | T46: =COUNTA(F36:F39) -> 0 | AO46: Laborar día festivo
Q47: Económicos de colchón | T47: 9 | AO47: [Especificar día]
AO48: [Especificar "No" del servicio]
AO49: [Especificar otro día si es necesario]
AO50: [Especificar "No" del servicio]
Q51: Nomenclatura
...

Sheet 13-A
D9: PERIODO : | E9: ='34-B'!E9 -> DEL 02 DE FEBRERO AL 01 DE MARZO 2026 | AA9: ORIGEN - DESTINO : | AB9: PARQUE MEXICO / METRO CHAPULTEPEC-PEDREGAL DE SAN NICOLAS / TORRES DE PADIERNA
D10: RUTA : | E10: 13-A | AA10: MODALIDAD : | AB10: EXPRESO
P11: Lunes a Viernes | AC11: Sábado | AP11: Domingo
F12: No de credencial | I12: Descansos en el periodo | P12: 1er Turno | T12: 2do Turno | W12: 3er Turno | Y12: Termino | AC12: 1er Turno | AG12: 2do Turno | AJ12: 3er Turno | AL12: Termino | AP12: 1er Turno | AT12: 2do Turno | AW12: 3er Turno | AY12: Termino
C13: No | D13: Economico | E13: Sistema | F13: 1er Turno | G13: 2do Turno | H13: 3er Turno | I13: L | J13: M | K13: Mi | L13: J | M13: V | N13: S | O13: D | P13: Hora inicio Turno 1 | Q13: Hora inicio en CC | R13: Lugar Inicio 1 | S13: Hora termino Turno 1 | T13: Lugar Inicio 2 | U13: Hora inicio 2 | V13: Hora termino Turno 2 | W13: Lugar Inicio 3 | X13: Hora Inicio Turno 3 | Y13: Hora Termino en CC | Z13: Lugar de termino CC | AA13: Termino en Modulo | AB13: Termino del Turno | AC13: Hora inicio Turno 1 __s__ | AD13: Hora inicio CC 1 __s__ | AE13: Lugar Inicio 1 __s__ | AF13: Hora termino Turno 1 __s__ | AG13: Lugar Inicio 2 __s__ | AH13: Hora inicio 2 __s__ | AI13: Hora termino Turno 2 __s__ | AJ13: Lugar Inicio 3 __s__ | AK13: Hora Inicio Turno 3 __s__ | AL13: Hora Termino en CC __s__ | AM13: Lugar de termino CC __s__ | AN13: Termino en Modulo __s__ | AO13: Termino del Turno __s__ | AP13: Hora inicio Turno 1 __d__ | AQ13: Hora inicio CC 1 __d__ | AR13: Lugar Inicio 1 __d__ | AS13: Hora termino Turno 1 __d__ | AT13: Lugar Inicio 2 __d__ | AU13: Hora inicio 2 __d__ | AV13: Hora termino Turno 2 __d__ | AW13: Lugar Inicio 3 __d__ | AX13: Hora Inicio Turno 3 __d__ | AY13: Hora Termino en CC __d__ | AZ13: Lugar de termino CC __d__ | BA13: Termino en Modulo __d__ | BB13: Termino del Turno __d__
I14: 2 | J14: =I14+1 -> 3 | K14: =J14+1 -> 4 | L14: =K14+1 -> 5 | M14: =L14+1 -> 6 | N14: =M14+1 -> 7 | O14: =N14+1 -> 8
I15: =O14+1 -> 9 | J15: =I15+1 -> 10 | K15: =J15+1 -> 11 | L15: =K15+1 -> 12 | M15: =L15+1 -> 13 | N15: =M15+1 -> 14 | O15: =N15+1 -> 15
I16: =O15+1 -> 16 | J16: =I16+1 -> 17 | K16: =J16+1 -> 18 | L16: =K16+1 -> 19 | M16: =L16+1 -> 20 | N16: =M16+1 -> 21 | O16: =N16+1 -> 22
I17: =O16+1 -> 23 | J17: =I17+1 -> 24 | K17: =J17+1 -> 25 | L17: =K17+1 -> 26 | M17: 27 | N17: 28 | O17: 1
Q20: 0.034722222 | U20: 0.020833333 | X20: 0.03125 | Y20: 0.020833333 | AA20: 0.010416667 | AB20: 0.29166667
C22: 1
C23: 2
C24: 3
C25: 4
C26: 5
C27: 6
C28: 7
C29: 8
C30: 9
C31: 10
C32: 11
C33: SERVICIO LA ANGOSTURA
C34: 11
C35: 12
C37: Cubre Descansos | Z37: Notas
I38: Servicios a cubrir
C39: No | D39: Economico | E39: Sistema | F39: 1er Turno | G39: 2do Turno | H39: 3er Turno | I39: L | J39: M | K39: Mi | L39: J | M39: V | N39: S | O39: D
C40: A
C41: B
E46: Jornada excepcional
I47: Presentarse
E48: Cred. | F48: Lugar | G48: Hora de Inicio | H48: Hora de Termino | I48: L | J48: M | K48: Mi | L48: J | M48: V | N48: S | O48: D | Y48: Para sistema E/S
E49: 5291 | F49: PMX | G49: 0.45833333 | H49: 0.79166667 | N49: D | O49: D | Q49: Económicos programados | U49: =COUNTA(D25:D35) -> 0 | Y49: Solo aplica a operadores de los turnos 1 y 2, turno 3 siempre es T/F
Q50: Cubre Descansos | U50: =COUNTA(F41:F43) -> 0 | Y50: ='34-B'!$Z$76 -> 0 | Z50: ='34-B'!$Z$77 -> 0 | AA50: ='34-B'!$Z$77 -> 0 | AB50: ='34-B'!$Z$77 -> 0 | AC50: ='34-B'!$Z$77 -> 0 | AD50: ='34-B'!$Z$77 -> 0 | AE50: ='34-B'!$Z$77 -> 0 | AF50: ='34-B'!$Z$77 -> 0 | AG50: ='34-B'!$Z$77 -> 0 | ... AJ50: ='34-B'!$Z$77 -> 0
Q51: Económicos de colchón | U51: 4 | Y51: ='34-B'!$Z$77 -> 0
Y52: ='34-B'!$Z$78 -> 0 | Z52: ='34-B'!$Z$79 -> 0 | AA52: ='34-B'!$Z$79 -> 0 | AB52: ='34-B'!$Z$79 -> 0 | AC52: ='34-B'!$Z$79 -> 0 | AD52: ='34-B'!$Z$79 -> 0 | AE52: ='34-B'!$Z$79 -> 0 | AF52: ='34-B'!$Z$79 -> 0 | AG52: ='34-B'!$Z$79 -> 0 | ... AJ52: ='34-B'!$Z$79 -> 0
Q53: Nomenclatura | Y53: ='34-B'!$Z$79 -> 0
R54: D | S54: Descanso
R55: P | S55: Presentarse | Y55: ESTE ROL PUEDE VARIAR DE ACUERDO A LAS NECESIDADES DEL SERVICIO
R56: A,B,C | S56: Cubre descansos | AS56: Laborar día festivo
...

Sheet 126
D9: PERIODO : | E9: ='34-B'!E9 -> DEL 02 DE FEBRERO AL 01 DE MARZO 2026 | AA9: ORIGEN - DESTINO : | AB9: MAGDALENA ATLITIC (CONTRERAS) - METRO COPILCO
D10: RUTA : | E10: 126 | AA10: MODALIDAD : | AB10: EXPRESO
P11: Lunes a Viernes | AC11: Sábado | AP11: Domingo
F12: No de credencial | I12: Descansos en el periodo | P12: 1er Turno | T12: 2do Turno | W12: 3er Turno | Y12: Termino | AC12: 1er Turno | AG12: 2do Turno | AJ12: 3er Turno | AL12: Termino | AP12: 1er Turno | AT12: 2do Turno | AW12: 3er Turno | AY12: Termino
C13: No | D13: Economico | E13: Sistema | F13: 1er Turno | G13: 2do Turno | H13: 3er Turno | I13: L | J13: M | K13: Mi | L13: J | M13: V | N13: S | O13: D | P13: Hora inicio Turno 1 | Q13: Hora inicio en CC | R13: Lugar Inicio 1 | S13: Hora termino Turno 1 | T13: Lugar Inicio 2 | U13: Hora inicio 2 | V13: Hora termino Turno 2 | W13: Lugar Inicio 3 | X13: Hora Inicio Turno 3 | Y13: Hora Termino en CC | Z13: Lugar de termino CC | AA13: Termino en Modulo | AB13: Termino del Turno | AC13: Hora inicio Turno 1 __s__ | AD13: Hora inicio CC 1 __s__ | AE13: Lugar Inicio 1 __s__ | AF13: Hora termino Turno 1 __s__ | AG13: Lugar Inicio 2 __s__ | AH13: Hora inicio 2 __s__ | AI13: Hora termino Turno 2 __s__ | AJ13: Lugar Inicio 3 __s__ | AK13: Hora Inicio Turno 3 __s__ | AL13: Hora Termino en CC __s__ | AM13: Lugar de termino CC __s__ | AN13: Termino en Modulo __s__ | AO13: Termino del Turno __s__ | AP13: Hora inicio Turno 1 __d__ | AQ13: Hora inicio CC 1 __d__ | AR13: Lugar Inicio 1 __d__ | AS13: Hora termino Turno 1 __d__ | AT13: Lugar Inicio 2 __d__ | AU13: Hora inicio 2 __d__ | AV13: Hora termino Turno 2 __d__ | AW13: Lugar Inicio 3 __d__ | AX13: Hora Inicio Turno 3 __d__ | AY13: Hora Termino en CC __d__ | AZ13: Lugar de termino CC __d__ | BA13: Termino en Modulo __d__ | BB13: Termino del Turno __d__
I14: 2 | J14: =I14+1 -> 3 | K14: =J14+1 -> 4 | L14: =K14+1 -> 5 | M14: =L14+1 -> 6 | N14: =M14+1 -> 7 | O14: =N14+1 -> 8
I15: =O14+1 -> 9 | J15: =I15+1 -> 10 | K15: =J15+1 -> 11 | L15: =K15+1 -> 12 | M15: =L15+1 -> 13 | N15: =M15+1 -> 14 | O15: =N15+1 -> 15
I16: =O15+1 -> 16 | J16: =I16+1 -> 17 | K16: =J16+1 -> 18 | L16: =K16+1 -> 19 | M16: =L16+1 -> 20 | N16: =M16+1 -> 21 | O16: =N16+1 -> 22
I17: =O16+1 -> 23 | J17: =I17+1 -> 24 | K17: =J17+1 -> 25 | L17: =K17+1 -> 26 | M17: 27 | N17: 28 | O17: 1
Q20: 0.027777778 | U20: 0.03125 | X20: 0.020833333 | Y20: 0.048611111 | AA20: 0.010416667 | AB20: 0.29166667 | BA20: 0.010416667
C21: 1
C22: 2
C23: 3
C24: 4
C25: 5
C26: 6
C27: 7
C28: 8
C29: 9
C31: Cubre Descansos | Z31: Notas
I32: Servicios a cubrir
C33: No | D33: Economico | E33: Sistema | F33: 1er Turno | G33: 2do Turno | H33: 3er Turno | I33: L | J33: M | K33: Mi | L33: J | M33: V | N33: S | O33: D
C34: A
C35: B
E40: Jornada excepcional
I41: Presentarse
E42: Cred. | F42: Lugar | G42: Hora de Inicio | H42: Hora de Termino | I42: L | J42: M | K42: Mi | L42: J | M42: V | N42: S | O42: D
Q43: Económicos programados | U43: =COUNTA(F24:F29) -> 0
Q44: Cubre Descansos | U44: =COUNTA(F35:F37) -> 0
Q45: Económicos de colchón | U45: =AD42 -> 0
Q48: Nomenclatura
R49: D | S49: Descanso | Z49: Para sistema E/S | AS49: Laborar día festivo
R50: A,B,C | S50: Presentarse | Z50: Solo aplica a operadores de los turnos 1 y 2, turno 3 siempre es T/F | AS50: [Especificar día]
S51: Cubre descansos | Z51: ='34-B'!$Z$76 -> 0 | AA51: ='34-B'!$Z$77 -> 0 | AB51: ='34-B'!$Z$77 -> 0 | AC51: ='34-B'!$Z$77 -> 0 | AD51: ='34-B'!$Z$77 -> 0 | AE51: ='34-B'!$Z$77 -> 0 | AF51: ='34-B'!$Z$77 -> 0 | AG51: ='34-B'!$Z$77 -> 0 | AH51: ='34-B'!$Z$77 -> 0 | ... AK51: ='34-B'!$Z$77 -> 0 | AS51: [Especificar "No" del servicio]
R52: M02 | S52: MODULO | Z52: ='34-B'!$Z$77 -> 0 | AS52: [Especificar otro día si es necesario]
R53: MGA | S53: MAGDALENA CONTRERAS | Z53: ='34-B'!$Z$78 -> 0 | AA53: ='34-B'!$Z$79 -> 0 | AB53: ='34-B'!$Z$79 -> 0 | AC53: ='34-B'!$Z$79 -> 0 | AD53: ='34-B'!$Z$79 -> 0 | AE53: ='34-B'!$Z$79 -> 0 | AF53: ='34-B'!$Z$79 -> 0 | AG53: ='34-B'!$Z$79 -> 0 | AH53: ='34-B'!$Z$79 -> 0 | ... AK53: ='34-B'!$Z$79 -> 0 | AS53: [Especificar "No" del servicio]
R54: CPI | S54: METRO COPILCO | Z54: ='34-B'!$Z$79 -> 0
Z56: ESTE ROL PUEDE VARIAR DE ACUERDO A LAS NECESIDADES DEL SERVICIO
D58: ELABORO | S58: AUTORIZO | AE58: Vo. Bo. | AQ58: PARTICIPO
E63: C. SALVADOR VILLASEÑOR GARCIA | S63: C. LUIS CARLOS OCHOA CEVALLOS | AE63: C. GABRIEL CONTRERAS TREJO | AQ63: JOEL HERNANDEZ VAZQUEZ
...

Sheet 2-A
D9: PERIODO : | E9: ='34-B'!E9 -> DEL 02 DE FEBRERO AL 01 DE MARZO 2026 | AA9: ORIGEN - DESTINO : | AB9: SAN PEDRO MARTIR POR FOVISSSTE - IZAZAGA (METRO PINO SUAREZ)
D10: RUTA : | E10: 2-A | AA10: MODALIDAD : | AB10: EXPRESO
P11: Lunes a Viernes | AC11: Sábado | AP11: Domingo
F12: No de credencial | I12: Descansos en el periodo | P12: 1er Turno | T12: 2do Turno | W12: 3er Turno | Y12: Termino | AC12: 1er Turno | AG12: 2do Turno | AJ12: 3er Turno | AL12: Termino | AP12: 1er Turno | AT12: 2do Turno | AW12: 3er Turno | AY12: Termino
C13: No | D13: Economico | E13: Sistema | F13: 1er Turno | G13: 2do Turno | H13: 3er Turno | I13: L | J13: M | K13: Mi | L13: J | M13: V | N13: S | O13: D | P13: Hora inicio Turno 1 | Q13: Hora inicio en CC | R13: Lugar Inicio 1 | S13: Hora termino Turno 1 | T13: Lugar Inicio 2 | U13: Hora inicio 2 | V13: Hora termino Turno 2 | W13: Lugar Inicio 3 | X13: Hora Inicio Turno 3 | Y13: Hora Termino en CC | Z13: Lugar de termino CC | AA13: Termino en Modulo | AB13: Termino del Turno | AC13: Hora inicio Turno 1 __s__ | AD13: Hora inicio CC 1 __s__ | AE13: Lugar Inicio 1 __s__ | AF13: Hora termino Turno 1 __s__ | AG13: Lugar Inicio 2 __s__ | AH13: Hora inicio 2 __s__ | AI13: Hora termino Turno 2 __s__ | AJ13: Lugar Inicio 3 __s__ | AK13: Hora Inicio Turno 3 __s__ | AL13: Hora Termino en CC __s__ | AM13: Lugar de termino CC __s__ | AN13: Termino en Modulo __s__ | AO13: Termino del Turno __s__ | AP13: Hora inicio Turno 1 __d__ | AQ13: Hora inicio CC 1 __d__ | AR13: Lugar Inicio 1 __d__ | AS13: Hora termino Turno 1 __d__ | AT13: Lugar Inicio 2 __d__ | AU13: Hora inicio 2 __d__ | AV13: Hora termino Turno 2 __d__ | AW13: Lugar Inicio 3 __d__ | AX13: Hora Inicio Turno 3 __d__ | AY13: Hora Termino en CC __d__ | AZ13: Lugar de termino CC __d__ | BA13: Termino en Modulo __d__ | BB13: Termino del Turno __d__
I14: 2 | J14: =I14+1 -> 3 | K14: =J14+1 -> 4 | L14: =K14+1 -> 5 | M14: =L14+1 -> 6 | N14: =M14+1 -> 7 | O14: =N14+1 -> 8
I15: =O14+1 -> 9 | J15: =I15+1 -> 10 | K15: =J15+1 -> 11 | L15: =K15+1 -> 12 | M15: =L15+1 -> 13 | N15: =M15+1 -> 14 | O15: =N15+1 -> 15
I16: =O15+1 -> 16 | J16: =I16+1 -> 17 | K16: =J16+1 -> 18 | L16: =K16+1 -> 19 | M16: =L16+1 -> 20 | N16: =M16+1 -> 21 | O16: =N16+1 -> 22
I17: =O16+1 -> 23 | J17: =I17+1 -> 24 | K17: =J17+1 -> 25 | L17: =K17+1 -> 26 | M17: 27 | N17: 28 | O17: 1
Q20: 0.020833333 | U20: 0.03125 | X20: 0.03125 | Y20: 0.020833333 | AA20: 0.010416667 | AB20: 0.29166667
C21: 1
C22: 2
C23: 3
C26: Cubre Descansos | Z26: Notas
I27: Servicios a cubrir
C28: No | D28: Economico | E28: Sistema | F28: 1er Turno | G28: 2do Turno | H28: 3er Turno | I28: L | J28: M | K28: Mi | L28: J | M28: V | N28: S | O28: D
C29: A
E35: Jornada excepcional
I36: Presentarse
E37: Cred. | G37: Hora de Inicio | H37: Hora de Termino | I37: L | J37: M | K37: Mi | L37: J | M37: V | N37: S | O37: D
Q38: Económicos programados | U38: =COUNTA(F22:F22) -> 0
Q39: Cubre Descansos | U39: =COUNTA(F30:F32) -> 0
Q40: Económicos de colchón | U40: 3
Q43: Nomenclatura
R44: D | S44: Descanso | Z44: Para sistema E/S | AS44: Laborar día festivo
R45: P | S45: Presentarse | Z45: Solo aplica a operadores de los turnos 1 y 2, turno 3 siempre es T/F | AS45: [Especificar día]
R46: A,B,C | S46: Cubre descansos | Z46: ='34-B'!$Z$76 -> 0 | AA46: ='34-B'!$Z$77 -> 0 | AB46: ='34-B'!$Z$77 -> 0 | AC46: ='34-B'!$Z$77 -> 0 | AD46: ='34-B'!$Z$77 -> 0 | AE46: ='34-B'!$Z$77 -> 0 | AF46: ='34-B'!$Z$77 -> 0 | AG46: ='34-B'!$Z$77 -> 0 | AH46: ='34-B'!$Z$77 -> 0 | ... AK46: ='34-B'!$Z$77 -> 0 | AS46: [Especificar "No" del servicio]
R47: M02 | S47: MODULO | Z47: ='34-B'!$Z$77 -> 0 | AS47: [Especificar otro día si es necesario]
R48: SPM | S48: SAN PEDRO MARTIR | Z48: ='34-B'!$Z$78 -> 0 | AA48: ='34-B'!$Z$79 -> 0 | AB48: ='34-B'!$Z$79 -> 0 | AC48: ='34-B'!$Z$79 -> 0 | AD48: ='34-B'!$Z$79 -> 0 | AE48: ='34-B'!$Z$79 -> 0 | AF48: ='34-B'!$Z$79 -> 0 | AG48: ='34-B'!$Z$79 -> 0 | AH48: ='34-B'!$Z$79 -> 0 | ... AK48: ='34-B'!$Z$79 -> 0 | AS48: [Especificar "No" del servicio]
R49: IZZ | S49: IZAZAGA | Z49: ='34-B'!$Z$79 -> 0
Z51: ESTE ROL PUEDE VARIAR DE ACUERDO A LAS NECESIDADES DEL SERVICIO
D53: ELABORO | S53: AUTORIZO | AJ53: Vo.Bo. | AQ53: PARTICIPO
E58: C. SALVADOR VILLASEÑOR GARCIA | S58: C. LUIS CARLOS OCHOA CEVALLOS | AF58: C. GABRIEL CONTRERAS TREJO | AQ58: JOEL HERNANDEZ VAZQUEZ
E59: CONTROLADOR DE TIEMPO "A" | S59: JUD. DE OPERACION | AF59: GERENTE MODULAR 2 | AQ59: REPRESENTANTE SINDICAL

Sheet 111-A
D9: PERIODO : | E9: ='34-B'!E9 -> DEL 02 DE FEBRERO AL 01 DE MARZO 2026 | AA9: ORIGEN - DESTINO : | AB9: CASETA DE COBRO - IZAZAGA (METRO PINO SUAREZ)
D10: RUTA : | E10: 111-A | AA10: MODALIDAD : | AB10: EXPRESO
P11: Lunes a Viernes | AC11: Sábado | AP11: Domingo
F12: No de credencial | I12: Descansos en el periodo | P12: 1er Turno | T12: 2do Turno | W12: 3er Turno | Y12: Termino | AC12: 1er Turno | AG12: 2do Turno | AJ12: 3er Turno | AL12: Termino | AP12: 1er Turno | AT12: 2do Turno | AW12: 3er Turno | AY12: Termino
C13: No | D13: Economico | E13: Sistema | F13: 1er Turno | G13: 2do Turno | H13: 3er Turno | I13: L | J13: M | K13: Mi | L13: J | M13: V | N13: S | O13: D | P13: Hora inicio Turno 1 | Q13: Hora inicio en CC | R13: Lugar Inicio 1 | S13: Hora termino Turno 1 | T13: Lugar Inicio 2 | U13: Hora inicio 2 | V13: Hora termino Turno 2 | W13: Lugar Inicio 3 | X13: Hora Inicio Turno 3 | Y13: Hora Termino en CC | Z13: Lugar de termino CC | AA13: Termino en Modulo | AB13: Termino del Turno | AC13: Hora inicio Turno 1 __s__ | AD13: Hora inicio CC 1 __s__ | AE13: Lugar Inicio 1 __s__ | AF13: Hora termino Turno 1 __s__ | AG13: Lugar Inicio 2 __s__ | AH13: Hora inicio 2 __s__ | AI13: Hora termino Turno 2 __s__ | AJ13: Lugar Inicio 3 __s__ | AK13: Hora Inicio Turno 3 __s__ | AL13: Hora Termino en CC __s__ | AM13: Lugar de termino CC __s__ | AN13: Termino en Modulo __s__ | AO13: Termino del Turno __s__ | AP13: Hora inicio Turno 1 __d__ | AQ13: Hora inicio CC 1 __d__ | AR13: Lugar Inicio 1 __d__ | AS13: Hora termino Turno 1 __d__ | AT13: Lugar Inicio 2 __d__ | AU13: Hora inicio 2 __d__ | AV13: Hora termino Turno 2 __d__ | AW13: Lugar Inicio 3 __d__ | AX13: Hora Inicio Turno 3 __d__ | AY13: Hora Termino en CC __d__ | AZ13: Lugar de termino CC __d__ | BA13: Termino en Modulo __d__ | BB13: Termino del Turno __d__
I14: 2 | J14: =I14+1 -> 3 | K14: =J14+1 -> 4 | L14: =K14+1 -> 5 | M14: =L14+1 -> 6 | N14: =M14+1 -> 7 | O14: =N14+1 -> 8
I15: =O14+1 -> 9 | J15: =I15+1 -> 10 | K15: =J15+1 -> 11 | L15: =K15+1 -> 12 | M15: =L15+1 -> 13 | N15: =M15+1 -> 14 | O15: =N15+1 -> 15
I16: =O15+1 -> 16 | J16: =I16+1 -> 17 | K16: =J16+1 -> 18 | L16: =K16+1 -> 19 | M16: =L16+1 -> 20 | N16: =M16+1 -> 21 | O16: =N16+1 -> 22
I17: =O16+1 -> 23 | J17: =I17+1 -> 24 | K17: =J17+1 -> 25 | L17: =K17+1 -> 26 | M17: 27 | N17: 28 | O17: 1
Q20: 0.027777778 | R20: 0.041666667 | S20: 0.052083333 | U20: 0.03125 | X20: 0.03125 | Z20: 0.041666667 | AA20: 0.010416667 | AB20: 0.29166667 | AC20: 0.041666667 | AD20: 0.027777778 | AE20: 0.041666667 | AF20: 0.052083333 | AH20: 0.03125 | AK20: 0.03125 | AM20: 0.041666667 | AN20: 0.010416667 | AQ20: 0.027777778 | AS20: 0.041666667 | AT20: 0.0069444444 | AU20: 0.020833333 | AV20: 0.052083333 | AX20: 0.03125 | BB20: 0.03125
C21: 4
C22: 5
C23: 6
C24: 7
C26: Cubre Descansos | Z26: Notas
I27: Servicios a cubrir
C28: No | D28: Economico | E28: Sistema | F28: 1er Turno | G28: 2do Turno | H28: 3er Turno | I28: L | J28: M | K28: Mi | L28: J | M28: V | N28: S | O28: D
E35: Jornada excepcional
I36: Presentarse
E37: Cred. | F37: Lugar | G37: Hora de Inicio | H37: Hora de Termino | I37: L | J37: M | K37: Mi | L37: J | M37: V | N37: S | O37: D
Q38: Económicos programados | U38: =COUNTA(F22:F23) -> 0
Q39: Cubre Descansos | U39: =COUNTA(F29:F32) -> 0
Q40: Económicos de colchón | U40: 3
Q43: Nomenclatura
R44: D | S44: Descanso | Z44: Para sistema E/S | AS44: Laborar día festivo
R45: P | S45: Presentarse | Z45: Solo aplica a operadores de los turnos 1 y 2, turno 3 siempre es T/F | AS45: [Especificar día]
R46: A,B,C | S46: Cubre descansos | Z46: ='34-B'!$Z$76 -> 0 | AA46: ='34-B'!$Z$77 -> 0 | AB46: ='34-B'!$Z$77 -> 0 | AC46: ='34-B'!$Z$77 -> 0 | AD46: ='34-B'!$Z$77 -> 0 | AE46: ='34-B'!$Z$77 -> 0 | AF46: ='34-B'!$Z$77 -> 0 | AG46: ='34-B'!$Z$77 -> 0 | AH46: ='34-B'!$Z$77 -> 0 | ... AK46: ='34-B'!$Z$77 -> 0 | AS46: [Especificar "No" del servicio]
R47: M02 | S47: MODULO | Z47: ='34-B'!$Z$77 -> 0 | AS47: [Especificar otro día si es necesario]
R48: CCB | S48: CASETA DE COBRO | Z48: ='34-B'!$Z$78 -> 0 | AA48: ='34-B'!$Z$79 -> 0 | AB48: ='34-B'!$Z$79 -> 0 | AC48: ='34-B'!$Z$79 -> 0 | AD48: ='34-B'!$Z$79 -> 0 | AE48: ='34-B'!$Z$79 -> 0 | AF48: ='34-B'!$Z$79 -> 0 | AG48: ='34-B'!$Z$79 -> 0 | AH48: ='34-B'!$Z$79 -> 0 | ... AK48: ='34-B'!$Z$79 -> 0 | AS48: [Especificar "No" del servicio]
R49: IZZ | S49: IZAZAGA | Z49: ='34-B'!$Z$79 -> 0
Z51: ESTE ROL PUEDE VARIAR DE ACUERDO A LAS NECESIDADES DEL SERVICIO
D53: ELABORO | S53: AUTORIZO | AE53: Vo. Bo. | AQ53: PARTICIPO
E58: SALVADOR VILLASEÑOR GARCIA | S58: C. LUIS CARLOS OCHOA CEVALLOS | AE58: C. GABRIEL CONTRERAS TREJO | AQ58: JOEL HERNANDEZ VAZQUEZ
E59: CONTROLADOR DE TIEMPO "A" | S59: JUD. DE OPERACION | AE59: GERENTE MODULAR 2 | AQ59: REPRESENTANTE SINDICAL

Sheet 300-B
D9: PERIODO : | E9: ='34-B'!E9 -> DEL 02 DE FEBRERO AL 01 DE MARZO 2026 | AA9: ORIGEN - DESTINO :
D10: RUTA : | AA10: MODALIDAD :
P11: Lunes a Viernes | AC11: Sábado | AP11: Domingo
F12: No de credencial | I12: Descansos en el periodo | P12: 1er Turno | T12: 2do Turno | W12: 3er Turno | Y12: Termino | AC12: 1er Turno | AG12: 2do Turno | AJ12: 3er Turno | AL12: Termino | AP12: 1er Turno | AT12: 2do Turno | AW12: 3er Turno | AY12: Termino
C13: No | D13: Economico | E13: Sistema | F13: 1er Turno | G13: 2do Turno | H13: 3er Turno | I13: L | J13: M | K13: Mi | L13: J | M13: V | N13: S | O13: D | P13: Hora inicio Turno 1 | Q13: Hora inicio en CC | R13: Lugar Inicio 1 | S13: Hora termino Turno 1 | T13: Lugar Inicio 2 | U13: Hora inicio 2 | V13: Hora termino Turno 2 | W13: Lugar Inicio 3 | X13: Hora Inicio Turno 3 | Y13: Hora Termino en CC | Z13: Lugar de termino CC | AA13: Termino en Modulo | AB13: Termino del Turno | AC13: Hora inicio Turno 1 __s__ | AD13: Hora inicio CC 1 __s__ | AE13: Lugar Inicio 1 __s__ | AF13: Hora termino Turno 1 __s__ | AG13: Lugar Inicio 2 __s__ | AH13: Hora inicio 2 __s__ | AI13: Hora termino Turno 2 __s__ | AJ13: Lugar Inicio 3 __s__ | AK13: Hora Inicio Turno 3 __s__ | AL13: Hora Termino en CC __s__ | AM13: Lugar de termino CC __s__ | AN13: Termino en Modulo __s__ | AO13: Termino del Turno __s__ | AP13: Hora inicio Turno 1 __d__ | AQ13: Hora inicio CC 1 __d__ | AR13: Lugar Inicio 1 __d__ | AS13: Hora termino Turno 1 __d__ | AT13: Lugar Inicio 2 __d__ | AU13: Hora inicio 2 __d__ | AV13: Hora termino Turno 2 __d__ | AW13: Lugar Inicio 3 __d__ | AX13: Hora Inicio Turno 3 __d__ | AY13: Hora Termino en CC __d__ | AZ13: Lugar de termino CC __d__ | BA13: Termino en Modulo __d__ | BB13: Termino del Turno __d__
I14: 3 | J14: 4 | K14: =J14+1 -> 5 | L14: =K14+1 -> 6 | M14: =L14+1 -> 7 | N14: =M14+1 -> 8 | O14: =N14+1 -> 9
I15: =O14+1 -> 10 | J15: =I15+1 -> 11 | K15: =J15+1 -> 12 | L15: =K15+1 -> 13 | M15: =L15+1 -> 14 | N15: =M15+1 -> 15 | O15: =N15+1 -> 16
I16: =O15+1 -> 17 | J16: =I16+1 -> 18 | K16: =J16+1 -> 19 | L16: =K16+1 -> 20 | M16: =L16+1 -> 21 | N16: =M16+1 -> 22 | O16: =N16+1 -> 23
I17: =O16+1 -> 24 | J17: =I17+1 -> 25 | K17: =J17+1 -> 26 | L17: =K17+1 -> 27 | M17: 28 | N17: 29 | O17: =N17+1 -> 30
Q20: 0.020833333 | U20: 0.041666667 | X20: 0.041666667 | Y20: 0.020833333 | AA20: 0.010416667 | AB20: 0.29166667
C21: 1 | P21: 0 | Q21: =P21+$Q$20 -> 0.020833333 | R21: PAX | S21: =IF(P21<TIMEVALUE("6:00"),P21+TIMEVALUE("7:30"),P21+TIMEVALUE("8:00")) -> 0.3125 | T21: =R21 -> PAX | U21: 0 | V21: =IF(U21+TIMEVALUE("8:00")>TIMEVALUE("20:00"),U21+TIMEVALUE("7:30"),U21+TIMEVALUE("8:00")) -> 0.33333333 | W21: =R21 -> PAX | X21: =V21-$X$20 -> 0.29166667 | Y21: 0 | Z21: =R21 -> PAX | AA21: =AB21-$AA$20 -> 0.57291667 | AB21: =X21+$AB$20 -> 0.58333333 | AC21: 0 | AD21: 0 | AE21: PAX | AF21: =IF(AC21<TIMEVALUE("6:00"),AC21+TIMEVALUE("7:30"),AC21+TIMEVALUE("8:00")) -> 0.3125 | AG21: =AE21 -> PAX | AH21: 0 | AI21: =IF(AH21+TIMEVALUE("8:00")>TIMEVALUE("20:00"),AH21+TIMEVALUE("7:30"),AH21+TIMEVALUE("8:00")) -> 0.33333333 | AJ21: =AE21 -> PAX | AK21: =AI21-$X$20 -> 0.29166667 | AL21: =AN21-$Y$20 -> 0.55208333 | AM21: =AE21 -> PAX | AN21: =AO21-$AA$20 -> 0.57291667 | AO21: =AK21+$AB$20 -> 0.58333333
C22: 2 | P22: 0 | Q22: =P22+$Q$20 -> 0.020833333 | R22: PAX | S22: =IF(P22<TIMEVALUE("6:00"),P22+TIMEVALUE("7:30"),P22+TIMEVALUE("8:00")) -> 0.3125 | T22: =R22 -> PAX | U22: 0 | V22: =IF(U22+TIMEVALUE("8:00")>TIMEVALUE("20:00"),U22+TIMEVALUE("7:30"),U22+TIMEVALUE("8:00")) -> 0.33333333 | W22: =R22 -> PAX | X22: =V22-$X$20 -> 0.29166667 | Y22: 0 | Z22: =R22 -> PAX | AA22: =AB22-$AA$20 -> 0.57291667 | AB22: =X22+$AB$20 -> 0.58333333 | AC22: 0 | AD22: 0 | AE22: PAX | AF22: =IF(AC22<TIMEVALUE("6:00"),AC22+TIMEVALUE("7:30"),AC22+TIMEVALUE("8:00")) -> 0.3125 | AG22: =AE22 -> PAX | AH22: 0 | AI22: =IF(AH22+TIMEVALUE("8:00")>TIMEVALUE("20:00"),AH22+TIMEVALUE("7:30"),AH22+TIMEVALUE("8:00")) -> 0.33333333 | AJ22: =AE22 -> PAX | AK22: =AI22-$X$20 -> 0.29166667 | AL22: =AN22-$Y$20 -> 0.55208333 | AM22: =AE22 -> PAX | AN22: =AO22-$AA$20 -> 0.57291667 | AO22: =AK22+$AB$20 -> 0.58333333
C23: 3 | P23: 0 | Q23: =P23+$Q$20 -> 0.020833333 | R23: PAX | S23: =IF(P23<TIMEVALUE("6:00"),P23+TIMEVALUE("7:30"),P23+TIMEVALUE("8:00")) -> 0.3125 | T23: =R23 -> PAX | U23: 0 | V23: =IF(U23+TIMEVALUE("8:00")>TIMEVALUE("20:00"),U23+TIMEVALUE("7:30"),U23+TIMEVALUE("8:00")) -> 0.33333333 | W23: =R23 -> PAX | X23: =V23-$X$20 -> 0.29166667 | Y23: 0 | Z23: =R23 -> PAX | AA23: =AB23-$AA$20 -> 0.57291667 | AB23: =X23+$AB$20 -> 0.58333333 | AC23: 0 | AD23: 0 | AE23: PAX | AF23: =IF(AC23<TIMEVALUE("6:00"),AC23+TIMEVALUE("7:30"),AC23+TIMEVALUE("8:00")) -> 0.3125 | AG23: =AE23 -> PAX | AH23: 0 | AI23: =IF(AH23+TIMEVALUE("8:00")>TIMEVALUE("20:00"),AH23+TIMEVALUE("7:30"),AH23+TIMEVALUE("8:00")) -> 0.33333333 | AJ23: =AE23 -> PAX | AK23: =AI23-$X$20 -> 0.29166667 | AL23: =AN23-$Y$20 -> 0.55208333 | AM23: =AE23 -> PAX | AN23: =AO23-$AA$20 -> 0.57291667 | AO23: =AK23+$AB$20 -> 0.58333333
C24: 4 | P24: 0 | Q24: =P24+$Q$20 -> 0.020833333 | R24: PAX | S24: =IF(P24<TIMEVALUE("6:00"),P24+TIMEVALUE("7:30"),P24+TIMEVALUE("8:00")) -> 0.3125 | T24: =R24 -> PAX | U24: 0 | V24: =IF(U24+TIMEVALUE("8:00")>TIMEVALUE("20:00"),U24+TIMEVALUE("7:30"),U24+TIMEVALUE("8:00")) -> 0.33333333 | W24: =R24 -> PAX | X24: =V24-$X$20 -> 0.29166667 | Y24: 0 | Z24: =R24 -> PAX | AA24: =AB24-$AA$20 -> 0.57291667 | AB24: =X24+$AB$20 -> 0.58333333
C25: 5 | P25: 0 | Q25: =P25+$Q$20 -> 0.020833333 | R25: PAX | S25: =IF(P25<TIMEVALUE("6:00"),P25+TIMEVALUE("7:30"),P25+TIMEVALUE("8:00")) -> 0.3125 | T25: =R25 -> PAX | U25: 0 | V25: =IF(U25+TIMEVALUE("8:00")>TIMEVALUE("20:00"),U25+TIMEVALUE("7:30"),U25+TIMEVALUE("8:00")) -> 0.33333333 | W25: =R25 -> PAX | X25: =V25-$X$20 -> 0.29166667 | Y25: 0 | Z25: =R25 -> PAX | AA25: =AB25-$AA$20 -> 0.57291667 | AB25: =X25+$AB$20 -> 0.58333333
C26: 6 | P26: 0 | Q26: =P26+$Q$20 -> 0.020833333 | R26: PAX | S26: =IF(P26<TIMEVALUE("6:00"),P26+TIMEVALUE("7:30"),P26+TIMEVALUE("8:00")) -> 0.3125 | T26: =R26 -> PAX | U26: 0 | V26: =IF(U26+TIMEVALUE("8:00")>TIMEVALUE("20:00"),U26+TIMEVALUE("7:30"),U26+TIMEVALUE("8:00")) -> 0.33333333 | W26: =R26 -> PAX | X26: =V26-$X$20 -> 0.29166667 | Y26: 0 | Z26: =R26 -> PAX | AA26: =AB26-$AA$20 -> 0.57291667 | AB26: =X26+$AB$20 -> 0.58333333
C27: 7 | P27: 0 | Q27: =P27+$Q$20 -> 0.020833333 | R27: PAX | S27: =IF(P27<TIMEVALUE("6:00"),P27+TIMEVALUE("7:30"),P27+TIMEVALUE("8:00")) -> 0.3125 | T27: =R27 -> PAX | U27: 0 | V27: =IF(U27+TIMEVALUE("8:00")>TIMEVALUE("20:00"),U27+TIMEVALUE("7:30"),U27+TIMEVALUE("8:00")) -> 0.33333333 | W27: PAX | X27: =V27-$X$20 -> 0.29166667 | Y27: 0 | Z27: =R27 -> PAX | AA27: =AB27-$AA$20 -> 0.57291667 | AB27: =X27+$AB$20 -> 0.58333333
H29: 6615
W32: Notas
C33: Cubre Descansos
I34: Servicios a cubrir
C35: No | D35: Economico | E35: Sistema | F35: 1er Turno | G35: 2do Turno | H35: 3er Turno | I35: L | J35: M | K35: Mi | L35: J | M35: V | N35: S | O35: D
E42: Jornada excepcional
I43: Presentarse
E44: Cred. | F44: Lugar | G44: Hora de Inicio | H44: Hora de Termino | I44: L | J44: M | K44: Mi | L44: J | M44: V | N44: S | O44: D
Q45: Económicos programados | U45: =COUNTA(F22:F27) -> 0
Q46: Cubre Descansos | U46: =COUNTA(F36:F39) -> 0
Q47: Económicos de colchón | U47: 3
Q50: Nomenclatura | W50: Para sistema E/S
R51: D | S51: Descanso | W51: Solo aplica a operadores de los turnos 1 y 2, turno 3 siempre es T/F
R52: P | S52: Presentarse | W52: ='34-B'!$Z$76 -> 0 | X52: ='34-B'!$Z$77 -> 0 | Y52: ='34-B'!$Z$77 -> 0 | Z52: ='34-B'!$Z$77 -> 0 | AA52: ='34-B'!$Z$77 -> 0 | AB52: ='34-B'!$Z$77 -> 0 | AC52: ='34-B'!$Z$77 -> 0 | AD52: ='34-B'!$Z$77 -> 0 | AE52: ='34-B'!$Z$77 -> 0 | ... AH52: ='34-B'!$Z$77 -> 0
R53: A,B,C | S53: Cubre descansos | W53: ='34-B'!$Z$77 -> 0
R54: M02 | S54: MODULO | W54: ='34-B'!$Z$78 -> 0 | X54: ='34-B'!$Z$79 -> 0 | Y54: ='34-B'!$Z$79 -> 0 | Z54: ='34-B'!$Z$79 -> 0 | AA54: ='34-B'!$Z$79 -> 0 | AB54: ='34-B'!$Z$79 -> 0 | AC54: ='34-B'!$Z$79 -> 0 | AD54: ='34-B'!$Z$79 -> 0 | AE54: ='34-B'!$Z$79 -> 0 | ... AH54: ='34-B'!$Z$79 -> 0 | AS54: Laborar día festivo
R55: PAX | S55: PASEO ACOXPA | W55: ='34-B'!$Z$79 -> 0 | AS55: [Especificar día]
R56: SFE | S56: SANTA FE | AS56: [Especificar "No" del servicio]
W57: ESTE ROL PUEDE VARIAR DE ACUERDO A LAS NECESIDADES DEL SERVICIO | AS57: [Especificar otro día si es necesario]
AS58: [Especificar "No" del servicio]
D60: ELABORO | S60: AUTORIZO | AE60: Vo. Bo. | AQ60: PARTICIPO
E65: C. SALVADOR VILLASEÑOR GARCIA | AE65: C. GABRIEL CONTRERAS TREJO | AQ65: JOEL HERNANDEZ VAZQUEZ
E66: CONTROLADOR DE TIEMPO "A" | AE66: GERENTE MODULAR 2 | AQ66: REPRESENTANTE SINDICAL

Sheet 17-F
D9: PERIODO : | E9: ='34-B'!E9 -> DEL 02 DE FEBRERO AL 01 DE MARZO 2026 | AA9: ORIGEN - DESTINO : | AB9: METRO TAXQUEÑA - SAN PEDRO MARTIR POR FOVISSSTE
D10: RUTA : | E10: 17-F | AA10: MODALIDAD : | AB10: ORDINARIO
P11: Lunes a Viernes | AC11: Sábado | AP11: Domingo
F12: No de credencial | I12: Descansos en el periodo | P12: 1er Turno | T12: 2do Turno | W12: 3er Turno | Y12: Termino | AC12: 1er Turno | AG12: 2do Turno | AJ12: 3er Turno | AL12: Termino | AP12: 1er Turno | AT12: 2do Turno | AW12: 3er Turno | AY12: Termino
C13: No | D13: Economico | E13: Sistema | F13: 1er Turno | G13: 2do Turno | H13: 3er Turno | I13: L | J13: M | K13: Mi | L13: J | M13: V | N13: S | O13: D | P13: Hora inicio Turno 1 | Q13: Hora inicio en CC | R13: Lugar Inicio 1 | S13: Hora termino Turno 1 | T13: Lugar Inicio 2 | U13: Hora inicio 2 | V13: Hora termino Turno 2 | W13: Lugar Inicio 3 | X13: Hora Inicio Turno 3 | Y13: Hora Termino en CC | Z13: Lugar de termino CC | AA13: Termino en Modulo | AB13: Termino del Turno | AC13: Hora inicio Turno 1 __s__ | AD13: Hora inicio CC 1 __s__ | AE13: Lugar Inicio 1 __s__ | AF13: Hora termino Turno 1 __s__ | AG13: Lugar Inicio 2 __s__ | AH13: Hora inicio 2 __s__ | AI13: Hora termino Turno 2 __s__ | AJ13: Lugar Inicio 3 __s__ | AK13: Hora Inicio Turno 3 __s__ | AL13: Hora Termino en CC __s__ | AM13: Lugar de termino CC __s__ | AN13: Termino en Modulo __s__ | AO13: Termino del Turno __s__ | AP13: Hora inicio Turno 1 __d__ | AQ13: Hora inicio CC 1 __d__ | AR13: Lugar Inicio 1 __d__ | AS13: Hora termino Turno 1 __d__ | AT13: Lugar Inicio 2 __d__ | AU13: Hora inicio 2 __d__ | AV13: Hora termino Turno 2 __d__ | AW13: Lugar Inicio 3 __d__ | AX13: Hora Inicio Turno 3 __d__ | AY13: Hora Termino en CC __d__ | AZ13: Lugar de termino CC __d__ | BA13: Termino en Modulo __d__ | BB13: Termino del Turno __d__
I14: 2 | J14: 3 | K14: =J14+1 -> 4 | L14: =K14+1 -> 5 | M14: =L14+1 -> 6 | N14: =M14+1 -> 7 | O14: =N14+1 -> 8
I15: =O14+1 -> 9 | J15: =I15+1 -> 10 | K15: =J15+1 -> 11 | L15: =K15+1 -> 12 | M15: =L15+1 -> 13 | N15: =M15+1 -> 14 | O15: =N15+1 -> 15
I16: =O15+1 -> 16 | J16: =I16+1 -> 17 | K16: =J16+1 -> 18 | L16: =K16+1 -> 19 | M16: =L16+1 -> 20 | N16: =M16+1 -> 21 | O16: =N16+1 -> 22
I17: =O16+1 -> 23 | J17: =I17+1 -> 24 | K17: =J17+1 -> 25 | L17: =K17+1 -> 26 | M17: 27 | N17: 28 | O17: 1
Q20: 0.027777778 | U20: 0.03125 | X20: 0.03125 | Y20: 0.020833333 | AA20: 0.010416667 | AB20: 0.29166667
C21: 1
C22: 2
C25: Cubre Descansos | Z25: Notas
I26: Servicios a cubrir
C27: No | D27: Economico | E27: Sistema | F27: 1er Turno | G27: 2do Turno | H27: 3er Turno | I27: L | J27: M | K27: Mi | L27: J | M27: V | N27: S | O27: D
E34: Jornada excepcional
I35: Presentarse
E36: Cred. | F36: Lugar | G36: Hora de Inicio | H36: Hora de Termino | I36: L | J36: M | K36: Mi | L36: J | M36: V | N36: S | O36: D
Q37: Económicos programados | U37: =COUNTA(F21:F23) -> 0
Q38: Cubre Descansos | U38: =COUNTA(F28:F31) -> 0
Q39: Económicos de colchón | U39: 1
Q42: Nomenclatura
R43: D | S43: Descanso | Z43: Para sistema E/S | AS43: Laborar día festivo
R44: P | S44: Presentarse | Z44: Solo aplica a operadores de los turnos 1 y 2, turno 3 siempre es T/F | AS44: [Especificar día]
R45: A,B,C | S45: Cubre descansos | Z45: ='34-B'!$Z$76 -> 0 | AA45: ='34-B'!$Z$77 -> 0 | AB45: ='34-B'!$Z$77 -> 0 | AC45: ='34-B'!$Z$77 -> 0 | AD45: ='34-B'!$Z$77 -> 0 | AE45: ='34-B'!$Z$77 -> 0 | AF45: ='34-B'!$Z$77 -> 0 | AG45: ='34-B'!$Z$77 -> 0 | AH45: ='34-B'!$Z$77 -> 0 | ... AK45: ='34-B'!$Z$77 -> 0 | AS45: [Especificar "No" del servicio]
R46: M02 | S46: MODULO | Z46: ='34-B'!$Z$77 -> 0 | AS46: [Especificar otro día si es necesario]
R47: SPM | S47: SAN PEDRO MARTIR | Z47: ='34-B'!$Z$78 -> 0 | AA47: ='34-B'!$Z$79 -> 0 | AB47: ='34-B'!$Z$79 -> 0 | AC47: ='34-B'!$Z$79 -> 0 | AD47: ='34-B'!$Z$79 -> 0 | AE47: ='34-B'!$Z$79 -> 0 | AF47: ='34-B'!$Z$79 -> 0 | AG47: ='34-B'!$Z$79 -> 0 | AH47: ='34-B'!$Z$79 -> 0 | ... AK47: ='34-B'!$Z$79 -> 0 | AS47: [Especificar "No" del servicio]
R48: TAX | S48: TAXQUEÑA | Z48: ='34-B'!$Z$79 -> 0
Z50: ESTE ROL PUEDE VARIAR DE ACUERDO A LAS NECESIDADES DEL SERVICIO
D52: ELABORO | S52: AUTORIZO | AJ52: Vo.Bo. | AQ52: PARTICIPO
E57: C. SALVADOR VILLASEÑOR GARCIA | S57: C. LUIS CARLOS OCHOA CEVALLOS | AF57: C. GABRIEL CONTRERAS TREJO | AQ57: JOEL HERNANDEZ VAZQUEZ
E58: CONTROLADOR DE TIEMPO "A" | S58: JUD. DE OPERACION | AF58: GERENTE MODULAR 2 | AQ58: REPRESENTANTE SINDICAL

Sheet 17-E
D9: PERIODO : | E9: ='34-B'!E9 -> DEL 02 DE FEBRERO AL 01 DE MARZO 2026 | AA9: ORIGEN - DESTINO : | AB9: METRO UNIVERSIDAD - SAN PEDRO MARTIR POR CARR. FEDERAL
D10: RUTA : | E10: 17-E | AA10: MODALIDAD : | AB10: ORDINARIO
P11: Lunes a Viernes | AC11: Sábado | AP11: Domingo
F12: No de credencial | I12: Descansos en el periodo | P12: 1er Turno | T12: 2do Turno | W12: 3er Turno | Y12: Termino | AC12: 1er Turno | AG12: 2do Turno | AJ12: 3er Turno | AL12: Termino | AP12: 1er Turno | AT12: 2do Turno | AW12: 3er Turno | AY12: Termino
C13: No | D13: Economico | E13: Sistema | F13: 1er Turno | G13: 2do Turno | H13: 3er Turno | I13: L | J13: M | K13: Mi | L13: J | M13: V | N13: S | O13: D | P13: Hora inicio Turno 1 | Q13: Hora inicio en CC | R13: Lugar Inicio 1 | S13: Hora termino Turno 1 | T13: Lugar Inicio 2 | U13: Hora inicio 2 | V13: Hora termino Turno 2 | W13: Lugar Inicio 3 | X13: Hora Inicio Turno 3 | Y13: Hora Termino en CC | Z13: Lugar de termino CC | AA13: Termino en Modulo | AB13: Termino del Turno | AC13: Hora inicio Turno 1 __s__ | AD13: Hora inicio CC 1 __s__ | AE13: Lugar Inicio 1 __s__ | AF13: Hora termino Turno 1 __s__ | AG13: Lugar Inicio 2 __s__ | AH13: Hora inicio 2 __s__ | AI13: Hora termino Turno 2 __s__ | AJ13: Lugar Inicio 3 __s__ | AK13: Hora Inicio Turno 3 __s__ | AL13: Hora Termino en CC __s__ | AM13: Lugar de termino CC __s__ | AN13: Termino en Modulo __s__ | AO13: Termino del Turno __s__ | AP13: Hora inicio Turno 1 __d__ | AQ13: Hora inicio CC 1 __d__ | AR13: Lugar Inicio 1 __d__ | AS13: Hora termino Turno 1 __d__ | AT13: Lugar Inicio 2 __d__ | AU13: Hora inicio 2 __d__ | AV13: Hora termino Turno 2 __d__ | AW13: Lugar Inicio 3 __d__ | AX13: Hora Inicio Turno 3 __d__ | AY13: Hora Termino en CC __d__ | AZ13: Lugar de termino CC __d__ | BA13: Termino en Modulo __d__ | BB13: Termino del Turno __d__
I14: 2 | J14: =I14+1 -> 3 | K14: =J14+1 -> 4 | L14: =K14+1 -> 5 | M14: =L14+1 -> 6 | N14: =M14+1 -> 7 | O14: =N14+1 -> 8
I15: =O14+1 -> 9 | J15: =I15+1 -> 10 | K15: =J15+1 -> 11 | L15: =K15+1 -> 12 | M15: =L15+1 -> 13 | N15: =M15+1 -> 14 | O15: =N15+1 -> 15
I16: =O15+1 -> 16 | J16: =I16+1 -> 17 | K16: =J16+1 -> 18 | L16: =K16+1 -> 19 | M16: =L16+1 -> 20 | N16: =M16+1 -> 21 | O16: =N16+1 -> 22
I17: =O16+1 -> 23 | J17: =I17+1 -> 24 | K17: =J17+1 -> 25 | L17: =K17+1 -> 26 | M17: 27 | N17: 28 | O17: 1
Q20: 0.027777778 | U20: 0.020833333 | X20: 0.020833333 | Y20: 0.027777778 | Z20: 0.03125 | AA20: 0.010416667 | AB20: 0.29166667 | AD20: 0.027777778 | AH20: 0.020833333 | AK20: 0.03125 | AM20: 0.020833333 | AN20: 0.010416667 | AQ20: 0.027777778 | AU20: 0.020833333 | AX20: 0.03125 | AZ20: 0.020833333 | BA20: 0.010416667
C21: 1
C22: 2
C25: Cubre Descansos | Z25: Notas
I26: Servicios a cubrir
C27: No | D27: Economico | E27: Sistema | F27: 1er Turno | G27: 2do Turno | H27: 3er Turno | I27: L | J27: M | K27: Mi | L27: J | M27: V | N27: S | O27: D
C28: A | N28: D | O28: D
E34: Jornada excepcional
I35: Presentarse
E36: Cred. | F36: Lugar | G36: Hora de Inicio | H36: Hora de Termino | I36: L | J36: M | K36: Mi | L36: J | M36: V | N36: S | O36: D
I37: P | J37: P | K37: P | L37: P | M37: P | N37: D | O37: D | Q37: Económicos programados | U37: 2
Q38: Cubre Descansos | U38: =COUNTA(F28:F31) -> 0
Q39: Económicos de colchón | U39: 0
Q42: Nomenclatura
R43: D | S43: Descanso | Z43: Para sistema E/S | AS43: Laborar día festivo
R44: P | S44: Presentarse | Z44: Solo aplica a operadores de los turnos 1 y 2, turno 3 siempre es T/F | AS44: [Especificar día]
R45: A,B,C | S45: Cubre descansos | Z45: ='34-B'!$Z$76 -> 0 | AA45: ='34-B'!$Z$77 -> 0 | AB45: ='34-B'!$Z$77 -> 0 | AC45: ='34-B'!$Z$77 -> 0 | AD45: ='34-B'!$Z$77 -> 0 | AE45: ='34-B'!$Z$77 -> 0 | AF45: ='34-B'!$Z$77 -> 0 | AG45: ='34-B'!$Z$77 -> 0 | AH45: ='34-B'!$Z$77 -> 0 | ... AK45: ='34-B'!$Z$77 -> 0 | AS45: [Especificar "No" del servicio]
R46: M02 | S46: MODULO | Z46: ='34-B'!$Z$77 -> 0 | AS46: [Especificar otro día si es necesario]
R47: SPM | S47: SAN PEDRO MARTIR | Z47: ='34-B'!$Z$78 -> 0 | AA47: ='34-B'!$Z$79 -> 0 | AB47: ='34-B'!$Z$79 -> 0 | AC47: ='34-B'!$Z$79 -> 0 | AD47: ='34-B'!$Z$79 -> 0 | AE47: ='34-B'!$Z$79 -> 0 | AF47: ='34-B'!$Z$79 -> 0 | AG47: ='34-B'!$Z$79 -> 0 | AH47: ='34-B'!$Z$79 -> 0 | ... AK47: ='34-B'!$Z$79 -> 0 | AS47: [Especificar "No" del servicio]
R48: UNV | S48: UNIVERSIDAD | Z48: ='34-B'!$Z$79 -> 0
Z50: ESTE ROL PUEDE VARIAR DE ACUERDO A LAS NECESIDADES DEL SERVICIO
D52: ELABORO | S52: AUTORIZO | AE52: Vo. Bo. | AQ52: PARTICIPO
D57: C. SALVADOR VILLASEÑOR GARCIA | S57: C. LUIS CARLOS OCHOA CEVALLOS | AE57: C. GABRIEL CONTRERAS TREJO | AQ57: JOEL HERNANDEZ VAZQUEZ
D58: CONTROLADOR DE TIEMPO "A" | S58: JUD. DE OPERACION | AE58: GERENTE MODULAR 2 | AQ58: REPRESENTANTE SINDICAL

Sheet 123-A
D9: PERIODO : | E9: ='34-B'!E9 -> DEL 02 DE FEBRERO AL 01 DE MARZO 2026 | AA9: ORIGEN - DESTINO : | AB9: PEDREGAL DE SAN NICOLAS POR GLORIETA - METRO UNIVERSIDAD
D10: RUTA : | E10: 123-A | AA10: MODALIDAD : | AB10: ORDINARIO
P11: Lunes a Viernes | AC11: Sábado | AP11: Domingo
F12: No de credencial | I12: Descansos en el periodo | P12: 1er Turno | T12: 2do Turno | W12: 3er Turno | Y12: Termino | AC12: 1er Turno | AG12: 2do Turno | AJ12: 3er Turno | AL12: Termino | AP12: 1er Turno | AT12: 2do Turno | AW12: 3er Turno | AY12: Termino
C13: No | D13: Economico | E13: Sistema | F13: 1er Turno | G13: 2do Turno | H13: 3er Turno | I13: L | J13: M | K13: Mi | L13: J | M13: V | N13: S | O13: D | P13: Hora inicio Turno 1 | Q13: Hora inicio en CC | R13: Lugar Inicio 1 | S13: Hora termino Turno 1 | T13: Lugar Inicio 2 | U13: Hora inicio 2 | V13: Hora termino Turno 2 | W13: Lugar Inicio 3 | X13: Hora Inicio Turno 3 | Y13: Hora Termino en CC | Z13: Lugar de termino CC | AA13: Termino en Modulo | AB13: Termino del Turno | AC13: Hora inicio Turno 1 __s__ | AD13: Hora inicio CC 1 __s__ | AE13: Lugar Inicio 1 __s__ | AF13: Hora termino Turno 1 __s__ | AG13: Lugar Inicio 2 __s__ | AH13: Hora inicio 2 __s__ | AI13: Hora termino Turno 2 __s__ | AJ13: Lugar Inicio 3 __s__ | AK13: Hora Inicio Turno 3 __s__ | AL13: Hora Termino en CC __s__ | AM13: Lugar de termino CC __s__ | AN13: Termino en Modulo __s__ | AO13: Termino del Turno __s__ | AP13: Hora inicio Turno 1 __d__ | AQ13: Hora inicio CC 1 __d__ | AR13: Lugar Inicio 1 __d__ | AS13: Hora termino Turno 1 __d__ | AT13: Lugar Inicio 2 __d__ | AU13: Hora inicio 2 __d__ | AV13: Hora termino Turno 2 __d__ | AW13: Lugar Inicio 3 __d__ | AX13: Hora Inicio Turno 3 __d__ | AY13: Hora Termino en CC __d__ | AZ13: Lugar de termino CC __d__ | BA13: Termino en Modulo __d__ | BB13: Termino del Turno __d__
I14: 2 | J14: =I14+1 -> 3 | K14: =J14+1 -> 4 | L14: =K14+1 -> 5 | M14: =L14+1 -> 6 | N14: =M14+1 -> 7 | O14: =N14+1 -> 8
I15: =O14+1 -> 9 | J15: =I15+1 -> 10 | K15: =J15+1 -> 11 | L15: =K15+1 -> 12 | M15: =L15+1 -> 13 | N15: =M15+1 -> 14 | O15: =N15+1 -> 15
I16: =O15+1 -> 16 | J16: =I16+1 -> 17 | K16: =J16+1 -> 18 | L16: =K16+1 -> 19 | M16: =L16+1 -> 20 | N16: =M16+1 -> 21 | O16: =N16+1 -> 22
I17: =O16+1 -> 23 | J17: =I17+1 -> 24 | K17: =J17+1 -> 25 | L17: =K17+1 -> 26 | M17: 27 | N17: 28 | O17: 1
Q20: 0.027777778 | U20: 0.020833333 | X20: 0.020833333 | Y20: 0.020833333 | AA20: 0.010416667 | AB20: 0.29166667
C21: 3
C22: 4
C24: Cubre Descansos | Z24: Notas
I25: Servicios a cubrir
C26: No | D26: Economico | E26: Sistema | F26: 1er Turno | G26: 2do Turno | H26: 3er Turno | I26: L | J26: M | K26: Mi | L26: J | M26: V | N26: S | O26: D
C27: A
E33: Jornada excepcional
I34: Presentarse
E35: Cred. | F35: Lugar | G35: Hora de Inicio | H35: Hora de Termino | I35: L | J35: M | K35: Mi | L35: J | M35: V | N35: S | O35: D
Q36: Económicos programados | U36: =COUNTA(F21:F22) -> 0
Q37: Cubre Descansos | U37: =COUNTA(F27:F30) -> 0
Q38: Económicos de colchón | U38: 2
Q41: Nomenclatura
R42: D | S42: Descanso | Z42: Para sistema E/S | AS42: Laborar día festivo
R43: P | S43: Presentarse | Z43: Solo aplica a operadores de los turnos 1 y 2, turno 3 siempre es T/F | AS43: [Especificar día]
R44: A,B,C | S44: Cubre descansos | Z44: ='34-B'!$Z$76 -> 0 | AA44: ='34-B'!$Z$77 -> 0 | AB44: ='34-B'!$Z$77 -> 0 | AC44: ='34-B'!$Z$77 -> 0 | AD44: ='34-B'!$Z$77 -> 0 | AE44: ='34-B'!$Z$77 -> 0 | AF44: ='34-B'!$Z$77 -> 0 | AG44: ='34-B'!$Z$77 -> 0 | AH44: ='34-B'!$Z$77 -> 0 | ... AK44: ='34-B'!$Z$77 -> 0 | AS44: [Especificar "No" del servicio]
R45: M02 | S45: MODULO | Z45: ='34-B'!$Z$77 -> 0 | AS45: [Especificar otro día si es necesario]
R46: PSN | S46: PEDREGAL DE SAN NICOLAS | Z46: ='34-B'!$Z$78 -> 0 | AA46: ='34-B'!$Z$79 -> 0 | AB46: ='34-B'!$Z$79 -> 0 | AC46: ='34-B'!$Z$79 -> 0 | AD46: ='34-B'!$Z$79 -> 0 | AE46: ='34-B'!$Z$79 -> 0 | AF46: ='34-B'!$Z$79 -> 0 | AG46: ='34-B'!$Z$79 -> 0 | AH46: ='34-B'!$Z$79 -> 0 | ... AK46: ='34-B'!$Z$79 -> 0 | AS46: [Especificar "No" del servicio]
R47: UNV | S47: METRO UNIVERSDAD | Z47: ='34-B'!$Z$79 -> 0
Z49: ESTE ROL PUEDE VARIAR DE ACUERDO A LAS NECESIDADES DEL SERVICIO
D51: ELABORO | S51: AUTORIZO | AE51: Vo. Bo. | AQ51: PARTICIPO
D56: C. SALVADOR VILLASEÑOR GARCIA | S56: C. LUIS CARLOS OCHOA CEVALLOS | AE56: C. GABRIEL CONTRERAS TREJO | AQ56: JOEL HERNANDEZ VAZQUEZ
D57: CONTROLADOR DE TIEMPO "A" | S57: JUD. DE OPERACION | AE57: GERENTE MODULAR 2 | AQ57: REPRESENTANTE SINDICAL

Sheet 125
D9: PERIODO : | E9: ='34-B'!E9 -> DEL 02 DE FEBRERO AL 01 DE MARZO 2026 | AA9: ORIGEN - DESTINO : | AB9: BOSQUE DEL PEDREGAL - METRO UNIVERSIDAD
D10: RUTA : | E10: 125 | AA10: MODALIDAD : | AB10: ORDINARIO
P11: Lunes a Viernes | AC11: Sábado | AP11: Domingo
F12: No de credencial | I12: Descansos en el periodo | P12: 1er Turno | T12: 2do Turno | W12: 3er Turno | Y12: Termino | AC12: 1er Turno | AG12: 2do Turno | AJ12: 3er Turno | AL12: Termino | AP12: 1er Turno | AT12: 2do Turno | AW12: 3er Turno | AY12: Termino
C13: No | D13: Economico | E13: Sistema | F13: 1er Turno | G13: 2do Turno | H13: 3er Turno | I13: L | J13: M | K13: Mi | L13: J | M13: V | N13: S | O13: D | P13: Hora inicio Turno 1 | Q13: Hora inicio en CC | R13: Lugar Inicio 1 | S13: Hora termino Turno 1 | T13: Lugar Inicio 2 | U13: Hora inicio 2 | V13: Hora termino Turno 2 | W13: Lugar Inicio 3 | X13: Hora Inicio Turno 3 | Y13: Hora Termino en CC | Z13: Lugar de termino CC | AA13: Termino en Modulo | AB13: Termino del Turno | AC13: Hora inicio Turno 1 __s__ | AD13: Hora inicio CC 1 __s__ | AE13: Lugar Inicio 1 __s__ | AF13: Hora termino Turno 1 __s__ | AG13: Lugar Inicio 2 __s__ | AH13: Hora inicio 2 __s__ | AI13: Hora termino Turno 2 __s__ | AJ13: Lugar Inicio 3 __s__ | AK13: Hora Inicio Turno 3 __s__ | AL13: Hora Termino en CC __s__ | AM13: Lugar de termino CC __s__ | AN13: Termino en Modulo __s__ | AO13: Termino del Turno __s__ | AP13: Hora inicio Turno 1 __d__ | AQ13: Hora inicio CC 1 __d__ | AR13: Lugar Inicio 1 __d__ | AS13: Hora termino Turno 1 __d__ | AT13: Lugar Inicio 2 __d__ | AU13: Hora inicio 2 __d__ | AV13: Hora termino Turno 2 __d__ | AW13: Lugar Inicio 3 __d__ | AX13: Hora Inicio Turno 3 __d__ | AY13: Hora Termino en CC __d__ | AZ13: Lugar de termino CC __d__ | BA13: Termino en Modulo __d__ | BB13: Termino del Turno __d__
I14: 2 | J14: =I14+1 -> 3 | K14: =J14+1 -> 4 | L14: =K14+1 -> 5 | M14: =L14+1 -> 6 | N14: =M14+1 -> 7 | O14: =N14+1 -> 8
I15: =O14+1 -> 9 | J15: =I15+1 -> 10 | K15: =J15+1 -> 11 | L15: =K15+1 -> 12 | M15: =L15+1 -> 13 | N15: =M15+1 -> 14 | O15: =N15+1 -> 15
I16: =O15+1 -> 16 | J16: =I16+1 -> 17 | K16: =J16+1 -> 18 | L16: =K16+1 -> 19 | M16: =L16+1 -> 20 | N16: =M16+1 -> 21 | O16: =N16+1 -> 22
I17: =O16+1 -> 23 | J17: =I17+1 -> 24 | K17: =J17+1 -> 25 | L17: =K17+1 -> 26 | M17: 27 | N17: 28 | O17: 1
Q20: 0.041666667 | U20: 0.020833333 | X20: 0.020833333 | Y20: 0.020833333 | AA20: 0.010416667 | AB20: 0.29166667
C21: 5
C22: 6
H28: 6615
Z31: Notas
C33: Cubre Descansos
I34: Servicios a cubrir
C35: No | D35: Economico | E35: Sistema | F35: 1er Turno | G35: 2do Turno | H35: 3er Turno | I35: L | J35: M | K35: Mi | L35: J | M35: V | N35: S | O35: D
C36: B | N36: D | O36: D
E42: Jornada excepcional
I43: Presentarse
E44: Cred. | F44: Lugar | G44: Hora de Inicio | H44: Hora de Termino | I44: L | J44: M | K44: Mi | L44: J | M44: V | N44: S | O44: D
Q45: Económicos programados | U45: 3
Q46: Cubre Descansos | U46: =COUNTA(F36:F39) -> 0
Q47: Económicos de colchón | U47: 4
Q50: Nomenclatura
R51: D | S51: Descanso | Z51: Para sistema E/S | AS51: Laborar día festivo
R52: P | S52: Presentarse | Z52: Solo aplica a operadores de los turnos 1 y 2, turno 3 siempre es T/F | AS52: [Especificar día]
R53: A,B,C | S53: Cubre descansos | Z53: ='34-B'!$Z$76 -> 0 | AA53: ='34-B'!$Z$77 -> 0 | AB53: ='34-B'!$Z$77 -> 0 | AC53: ='34-B'!$Z$77 -> 0 | AD53: ='34-B'!$Z$77 -> 0 | AE53: ='34-B'!$Z$77 -> 0 | AF53: ='34-B'!$Z$77 -> 0 | AG53: ='34-B'!$Z$77 -> 0 | AH53: ='34-B'!$Z$77 -> 0 | ... AK53: ='34-B'!$Z$77 -> 0 | AS53: [Especificar "No" del servicio]
R54: M02 | S54: MODULO | Z54: ='34-B'!$Z$77 -> 0 | AS54: [Especificar otro día si es necesario]
R55: BPD | S55: BOSQUES | Z55: ='34-B'!$Z$78 -> 0 | AA55: ='34-B'!$Z$79 -> 0 | AB55: ='34-B'!$Z$79 -> 0 | AC55: ='34-B'!$Z$79 -> 0 | AD55: ='34-B'!$Z$79 -> 0 | AE55: ='34-B'!$Z$79 -> 0 | AF55: ='34-B'!$Z$79 -> 0 | AG55: ='34-B'!$Z$79 -> 0 | AH55: ='34-B'!$Z$79 -> 0 | ... AK55: ='34-B'!$Z$79 -> 0 | AS55: [Especificar "No" del servicio]
R56: UNV | S56: UNIVERSDAD | Z56: ='34-B'!$Z$79 -> 0
Z58: ESTE ROL PUEDE VARIAR DE ACUERDO A LAS NECESIDADES DEL SERVICIO
D60: ELABORO | S60: AUTORIZO | AE60: Vo. Bo. | AQ60: PARTICIPO
D65: C. SALVADOR VILLASEÑOR GARCIA | S65: C. LUIS CARLOS OCHOA CEVALLOS | AE65: C. GABRIEL CONTRERAS TREJO | AQ65: JOEL HERNANDEZ VAZQUEZ
D66: CONTROLADOR DE TIEMPO "A" | S66: JUD. DE OPERACION | AE66: GERENTE MODULAR 2 | AQ66: REPRESENTANTE SINDICAL

Sheet 128
D9: PERIODO : | E9: ='34-B'!E9 -> DEL 02 DE FEBRERO AL 01 DE MARZO 2026 | AA9: ORIGEN - DESTINO : | AB9: SAN BERNABE / OYAMEL - METRO UNIVERSIDAD
D10: RUTA : | E10: 128 | AA10: MODALIDAD : | AB10: ORDINARIO
P11: Lunes a Viernes | AC11: Sábado | AP11: Domingo
F12: No de credencial | I12: Descansos en el periodo | P12: 1er Turno | T12: 2do Turno | W12: 3er Turno | Y12: Termino | AC12: 1er Turno | AG12: 2do Turno | AJ12: 3er Turno | AL12: Termino | AP12: 1er Turno | AT12: 2do Turno | AW12: 3er Turno | AY12: Termino
C13: No | D13: Economico | E13: Sistema | F13: 1er Turno | G13: 2do Turno | H13: 3er Turno | I13: L | J13: M | K13: Mi | L13: J | M13: V | N13: S | O13: D | P13: Hora inicio Turno 1 | Q13: Hora inicio en CC | R13: Lugar Inicio 1 | S13: Hora termino Turno 1 | T13: Lugar Inicio 2 | U13: Hora inicio 2 | V13: Hora termino Turno 2 | W13: Lugar Inicio 3 | X13: Hora Inicio Turno 3 | Y13: Hora Termino en CC | Z13: Lugar de termino CC | AA13: Termino en Modulo | AB13: Termino del Turno | AC13: Hora inicio Turno 1 __s__ | AD13: Hora inicio CC 1 __s__ | AE13: Lugar Inicio 1 __s__ | AF13: Hora termino Turno 1 __s__ | AG13: Lugar Inicio 2 __s__ | AH13: Hora inicio 2 __s__ | AI13: Hora termino Turno 2 __s__ | AJ13: Lugar Inicio 3 __s__ | AK13: Hora Inicio Turno 3 __s__ | AL13: Hora Termino en CC __s__ | AM13: Lugar de termino CC __s__ | AN13: Termino en Modulo __s__ | AO13: Termino del Turno __s__ | AP13: Hora inicio Turno 1 __d__ | AQ13: Hora inicio CC 1 __d__ | AR13: Lugar Inicio 1 __d__ | AS13: Hora termino Turno 1 __d__ | AT13: Lugar Inicio 2 __d__ | AU13: Hora inicio 2 __d__ | AV13: Hora termino Turno 2 __d__ | AW13: Lugar Inicio 3 __d__ | AX13: Hora Inicio Turno 3 __d__ | AY13: Hora Termino en CC __d__ | AZ13: Lugar de termino CC __d__ | BA13: Termino en Modulo __d__ | BB13: Termino del Turno __d__
I14: 2 | J14: =I14+1 -> 3 | K14: =J14+1 -> 4 | L14: =K14+1 -> 5 | M14: =L14+1 -> 6 | N14: =M14+1 -> 7 | O14: =N14+1 -> 8
I15: =O14+1 -> 9 | J15: =I15+1 -> 10 | K15: =J15+1 -> 11 | L15: =K15+1 -> 12 | M15: =L15+1 -> 13 | N15: =M15+1 -> 14 | O15: =N15+1 -> 15
I16: =O15+1 -> 16 | J16: =I16+1 -> 17 | K16: =J16+1 -> 18 | L16: =K16+1 -> 19 | M16: =L16+1 -> 20 | N16: =M16+1 -> 21 | O16: =N16+1 -> 22
I17: =O16+1 -> 23 | J17: =I17+1 -> 24 | K17: =J17+1 -> 25 | L17: =K17+1 -> 26 | M17: 27 | N17: 28 | O17: 1
Q20: 0.027777778 | U20: 0.020833333 | X20: 0.020833333 | Y20: 0.020833333 | AA20: 0.010416667 | AB20: 0.29166667 | AL20: 0.020833333 | AN20: 0.010416667
C21: 7
C22: 8
C25: Cubre Descansos | Z25: Notas
I26: Servicios a cubrir
C27: No | D27: Economico | E27: Sistema | F27: 1er Turno | G27: 2do Turno | H27: 3er Turno | I27: L | J27: M | K27: Mi | L27: J | M27: V | N27: S | O27: D
C28: B
E34: Jornada excepcional
I35: Presentarse
E36: Cred. | G36: Hora de Inicio | H36: Hora de Termino | I36: L | J36: M | K36: Mi | L36: J | M36: V | N36: S | O36: D
I37: P | J37: P | K37: P | L37: P | M37: P | N37: D | O37: D | Q37: Económicos programados | U37: =COUNTA(F21:F24) -> 0
Q38: Cubre Descansos | U38: =COUNTA(F28:F31) -> 0
Q39: Económicos de colchón | U39: 1
Q42: Nomenclatura | AS42: Laborar día festivo
R43: D | S43: Descanso | Z43: Para sistema E/S | AS43: [Especificar día]
R44: P | S44: Presentarse | Z44: Solo aplica a operadores de los turnos 1 y 2, turno 3 siempre es T/F | AS44: [Especificar "No" del servicio]
R45: A,B,C | S45: Cubre descansos | Z45: ='34-B'!$Z$76 -> 0 | AA45: ='34-B'!$Z$77 -> 0 | AB45: ='34-B'!$Z$77 -> 0 | AC45: ='34-B'!$Z$77 -> 0 | AD45: ='34-B'!$Z$77 -> 0 | AE45: ='34-B'!$Z$77 -> 0 | AF45: ='34-B'!$Z$77 -> 0 | AG45: ='34-B'!$Z$77 -> 0 | AH45: ='34-B'!$Z$77 -> 0 | ... AK45: ='34-B'!$Z$77 -> 0 | AS45: [Especificar otro día si es necesario]
R46: M02 | S46: MODULO | Z46: ='34-B'!$Z$77 -> 0 | AS46: [Especificar "No" del servicio]
R47: SBN | S47: SAN BERNABE OYAMEL | Z47: ='34-B'!$Z$78 -> 0 | AA47: ='34-B'!$Z$79 -> 0 | AB47: ='34-B'!$Z$79 -> 0 | AC47: ='34-B'!$Z$79 -> 0 | AD47: ='34-B'!$Z$79 -> 0 | AE47: ='34-B'!$Z$79 -> 0 | AF47: ='34-B'!$Z$79 -> 0 | AG47: ='34-B'!$Z$79 -> 0 | AH47: ='34-B'!$Z$79 -> 0 | ... AK47: ='34-B'!$Z$79 -> 0
R48: UNV | S48: UNIVERSDAD | Z48: ='34-B'!$Z$79 -> 0
Z50: ESTE ROL PUEDE VARIAR DE ACUERDO A LAS NECESIDADES DEL SERVICIO
D52: ELABORO | S52: AUTORIZO | AE52: Vo. Bo. | AQ52: PARTICIPO
D57: C. SALVADOR VILLASEÑOR GARCIA | S57: C. LUIS CARLOS OCHOA CEVALLOS | AF57: C. GABRIEL CONTRERAS TREJO | AQ57: JOEL HERNANDEZ VAZQUEZ
D58: CONTROLADOR DE TIEMPO "A" | S58: JUD. DE OPERACION | AF58: GERENTE MODULAR 2 | AQ58: REPRESENTANTE SINDICAL

Sheet 134-C
D9: PERIODO : | E9: ='34-B'!E9 -> DEL 02 DE FEBRERO AL 01 DE MARZO 2026 | AA9: ORIGEN - DESTINO : | AB9: SANTO TOMAS AJUSCO - METRO UNIVERSIDAD
D10: RUTA : | E10: 134-C | AA10: MODALIDAD : | AB10: ORDINARIO
P11: Lunes a Viernes | AC11: Sábado | AP11: Domingo
F12: No de credencial | I12: Descansos en el periodo | P12: 1er Turno | T12: 2do Turno | W12: 3er Turno | Y12: Termino | AC12: 1er Turno | AG12: 2do Turno | AJ12: 3er Turno | AL12: Termino | AP12: 1er Turno | AT12: 2do Turno | AW12: 3er Turno | AY12: Termino
C13: No | D13: Economico | E13: Sistema | F13: 1er Turno | G13: 2do Turno | H13: 3er Turno | I13: L | J13: M | K13: Mi | L13: J | M13: V | N13: S | O13: D | P13: Hora inicio Turno 1 | Q13: Hora inicio en CC | R13: Lugar Inicio 1 | S13: Hora termino Turno 1 | T13: Lugar Inicio 2 | U13: Hora inicio 2 | V13: Hora termino Turno 2 | W13: Lugar Inicio 3 | X13: Hora Inicio Turno 3 | Y13: Hora Termino en CC | Z13: Lugar de termino CC | AA13: Termino en Modulo | AB13: Termino del Turno | AC13: Hora inicio Turno 1 __s__ | AD13: Hora inicio CC 1 __s__ | AE13: Lugar Inicio 1 __s__ | AF13: Hora termino Turno 1 __s__ | AG13: Lugar Inicio 2 __s__ | AH13: Hora inicio 2 __s__ | AI13: Hora termino Turno 2 __s__ | AJ13: Lugar Inicio 3 __s__ | AK13: Hora Inicio Turno 3 __s__ | AL13: Hora Termino en CC __s__ | AM13: Lugar de termino CC __s__ | AN13: Termino en Modulo __s__ | AO13: Termino del Turno __s__ | AP13: Hora inicio Turno 1 __d__ | AQ13: Hora inicio CC 1 __d__ | AR13: Lugar Inicio 1 __d__ | AS13: Hora termino Turno 1 __d__ | AT13: Lugar Inicio 2 __d__ | AU13: Hora inicio 2 __d__ | AV13: Hora termino Turno 2 __d__ | AW13: Lugar Inicio 3 __d__ | AX13: Hora Inicio Turno 3 __d__ | AY13: Hora Termino en CC __d__ | AZ13: Lugar de termino CC __d__ | BA13: Termino en Modulo __d__ | BB13: Termino del Turno __d__
I14: 2 | J14: =I14+1 -> 3 | K14: =J14+1 -> 4 | L14: =K14+1 -> 5 | M14: =L14+1 -> 6 | N14: =M14+1 -> 7 | O14: =N14+1 -> 8
I15: =O14+1 -> 9 | J15: =I15+1 -> 10 | K15: =J15+1 -> 11 | L15: =K15+1 -> 12 | M15: =L15+1 -> 13 | N15: =M15+1 -> 14 | O15: =N15+1 -> 15
I16: =O15+1 -> 16 | J16: =I16+1 -> 17 | K16: =J16+1 -> 18 | L16: =K16+1 -> 19 | M16: =L16+1 -> 20 | N16: =M16+1 -> 21 | O16: =N16+1 -> 22
I17: =O16+1 -> 23 | J17: =I17+1 -> 24 | K17: =J17+1 -> 25 | L17: =K17+1 -> 26 | M17: 27 | N17: 28 | O17: 1
Q20: 0.041666667 | U20: 0.020833333 | X20: 0.041666667 | Y20: 0.020833333 | AA20: 0.010416667 | AB20: 0.29166667
C21: 9
C22: 10
C23: 11
H29: 6615
Z32: Notas
C34: Cubre Descansos
I35: Servicios a cubrir
C36: No | D36: Economico | E36: Sistema | G36: 2do Turno | H36: 3er Turno | I36: L | J36: M | K36: Mi | L36: J | M36: V | N36: S | O36: D
N37: D | O37: D
E43: Jornada excepcional
I44: Presentarse
E45: Cred. | F45: Lugar | G45: Hora de Inicio | H45: Hora de Termino | I45: L | J45: M | K45: Mi | L45: J | M45: V | N45: S | O45: D
N46: D | O46: D | Q46: Económicos programados | U46: =COUNTA(F21:F31) -> 0
Q47: Cubre Descansos | U47: =COUNTA(F37:F40) -> 0
Q48: Económicos de colchón | U48: =AD45 -> 0
Q51: Nomenclatura
R52: D | S52: Descanso | Z52: Para sistema E/S | AS52: Laborar día festivo
R53: P | S53: Presentarse | Z53: Solo aplica a operadores de los turnos 1 y 2, turno 3 siempre es T/F | AS53: [Especificar día]
